---
title: C28105
ms.date: 11/04/2016
ms.topic: reference
f1_keywords:
- C28105
helpviewer_keywords:
- C28105
ms.assetid: 5afdec78-30eb-470c-980f-93d0cb3e74cc
author: mikeblome
ms.author: mblome
manager: markl
ms.workload:
- multiple
ms.openlocfilehash: 8053149db4b47639bd53961090db6b8bbbef80a9
ms.sourcegitcommit: 485ffaedb1ade71490f11cf05962add1718945cc
ms.translationtype: MT
ms.contentlocale: fr-FR
ms.lasthandoff: 10/16/2019
ms.locfileid: "72448403"
---
# <a name="c28105"></a>C28105
AVERTISSEMENT C28105 : fuite de ressource en raison d’une exception

 La ressource spécifiée n’est pas libérée lorsqu’une exception est levée. L’instruction spécifiée par le chemin d’accès peut lever une exception. Cet avertissement est semblable à Warning [C28103](../code-quality/c28103.md), à ceci près qu’une exception est impliquée dans ce cas.

## <a name="example"></a>Exemple
 L'exemple de code suivant génère cet avertissement :

```
res = KeSaveFloatingPointState(buffer);

res = AllocateResource(Resource);
char *p2 = new char[10]; // could throw

delete[] p2;
FreeResource(Resource)
```

 L'exemple de code suivant évite cet avertissement :

```
res = AllocateResource(Resource);
char *p2;

try {
    p2 = new char[10];
} catch (std::bad_alloc *e) {
    // just handle the throw
    ;
}
FreeResource(Resource)
```
