---
title: C28105
ms.date: 11/04/2016
ms.topic: reference
f1_keywords:
- C28105
helpviewer_keywords:
- C28105
ms.assetid: 5afdec78-30eb-470c-980f-93d0cb3e74cc
author: corob-msft
ms.author: corob
manager: markl
ms.workload:
- multiple
ms.openlocfilehash: 35f138288cc46e1b7a4be34b530f07df7f66caff
ms.sourcegitcommit: 68f893f6e472df46f323db34a13a7034dccad25a
ms.translationtype: MT
ms.contentlocale: fr-FR
ms.lasthandoff: 02/15/2020
ms.locfileid: "77270191"
---
# <a name="c28105"></a>C28105
AVERTISSEMENT C28105 : fuite de ressource en raison d’une exception

 La ressource spécifiée n’est pas libérée lorsqu’une exception est levée. L’instruction spécifiée par le chemin d’accès peut lever une exception. Cet avertissement est semblable à Warning [C28103](../code-quality/c28103.md), à ceci près qu’une exception est impliquée dans ce cas.

## <a name="example"></a>Exemple
 L'exemple de code suivant génère cet avertissement :

```cpp
res = KeSaveFloatingPointState(buffer);

res = AllocateResource(Resource);
char *p2 = new char[10]; // could throw

delete[] p2;
FreeResource(Resource)
```

 L'exemple de code suivant évite cet avertissement :

```cpp
res = AllocateResource(Resource);
char *p2;

try {
    p2 = new char[10];
} catch (std::bad_alloc *e) {
    // just handle the throw
    ;
}
FreeResource(Resource)
```
