---
title: C28105
ms.date: 11/04/2016
ms.topic: reference
f1_keywords:
- C28105
helpviewer_keywords:
- C28105
ms.assetid: 5afdec78-30eb-470c-980f-93d0cb3e74cc
author: mikeblome
ms.author: mblome
manager: wpickett
ms.workload:
- multiple
ms.openlocfilehash: c0906c1e876a13049dfe1d1e7727c22528f8e8ed
ms.sourcegitcommit: 21d667104199c2493accec20c2388cf674b195c3
ms.translationtype: MT
ms.contentlocale: fr-FR
ms.lasthandoff: 02/08/2019
ms.locfileid: "55946091"
---
# <a name="c28105"></a>C28105
Avertissement C28105 : Fuite de la ressource en raison d’une exception

 La ressource spécifiée n’est pas libérée lorsqu’une exception est levée. L’instruction spécifiée par le chemin d’accès peut lever une exception. Cet avertissement est similaire à avertissement [C28103](../code-quality/c28103.md), sauf que dans ce cas une exception est impliquée.

## <a name="example"></a>Exemple
 L'exemple de code suivant génère cet avertissement :

```
res = KeSaveFloatingPointState(buffer);

res = AllocateResource(Resource);
char *p2 = new char[10]; // could throw

delete[] p2;
FreeResource(Resource)
```

 L'exemple de code suivant évite cet avertissement :

```
res = AllocateResource(Resource);
char *p2;

try {
    p2 = new char[10];
} catch (std::bad_alloc *e) {
    // just handle the throw
    ;
}
FreeResource(Resource)
```