---
title: C28105
ms.date: 11/04/2016
ms.topic: reference
f1_keywords:
- C28105
helpviewer_keywords:
- C28105
ms.assetid: 5afdec78-30eb-470c-980f-93d0cb3e74cc
author: mikeblome
ms.author: mblome
manager: markl
ms.workload:
- multiple
ms.openlocfilehash: f6a0b92c67840343a7ae1ea0986b27c76375e2e1
ms.sourcegitcommit: 174c992ecdc868ecbf7d3cee654bbc2855aeb67d
ms.translationtype: MT
ms.contentlocale: fr-FR
ms.lasthandoff: 12/06/2019
ms.locfileid: "74879072"
---
# <a name="c28105"></a>C28105
AVERTISSEMENT C28105 : fuite de ressource en raison d’une exception

 La ressource spécifiée n’est pas libérée lorsqu’une exception est levée. L’instruction spécifiée par le chemin d’accès peut lever une exception. Cet avertissement est semblable à Warning [C28103](../code-quality/c28103.md), à ceci près qu’une exception est impliquée dans ce cas.

## <a name="example"></a>Exemple
 L'exemple de code suivant génère cet avertissement :

```cpp
res = KeSaveFloatingPointState(buffer);

res = AllocateResource(Resource);
char *p2 = new char[10]; // could throw

delete[] p2;
FreeResource(Resource)
```

 L'exemple de code suivant évite cet avertissement :

```cpp
res = AllocateResource(Resource);
char *p2;

try {
    p2 = new char[10];
} catch (std::bad_alloc *e) {
    // just handle the throw
    ;
}
FreeResource(Resource)
```
